Workbook

Sheet BEBIDAS
A1: Código | B1: Descrição | C1: CUSTO | D1: CUSTO_MEDIO | E1: Saídas | F1: Qtd. PDV | G1: Estoque | H1: Estoque(dias) | I1: Sugestão(Un.) | J1: Qtd. mínima(Un.) | K1: CATEGORIA
A2: 7898915949193 | B2: CERVEJA PURO MALTE IMPERIO LATA 473ML | C2: =XLOOKUP(A2, 'Estoque 2026-01-27.xlsx'!$C:$C, 'Estoque 2026-01-27.xlsx'!$L:$L, "") | D2: =XLOOKUP(A2, 'Estoque 2026-01-27.xlsx'!$C:$C, 'Estoque 2026-01-27.xlsx'!$M:$M, "") | E2: 232 | F2: 18 | G2: 0 | H2: 0 | I2: 54 | J2: 0 | K2: BEBIDAS
A3: 7894900027013 | B3: REFRIGERANTE COCA-COLA TRADICIONAL PET 2L | C3: =XLOOKUP(A3, 'Estoque 2026-01-27.xlsx'!$C:$C, 'Estoque 2026-01-27.xlsx'!$L:$L, "") | D3: =XLOOKUP(A3, 'Estoque 2026-01-27.xlsx'!$C:$C, 'Estoque 2026-01-27.xlsx'!$M:$M, "") | E3: 117 | F3: 24 | G3: 5 | H3: 1 | I3: 22 | J3: 0 | K3: BEBIDAS
A4: 7891149010509 | B4: CERVEJA CHOPP BRAHMA LATA 350ML | C4: =XLOOKUP(A4, 'Estoque 2026-01-27.xlsx'!$C:$C, 'Estoque 2026-01-27.xlsx'!$L:$L, "") | D4: =XLOOKUP(A4, 'Estoque 2026-01-27.xlsx'!$C:$C, 'Estoque 2026-01-27.xlsx'!$M:$M, "") | E4: 35 | F4: 0 | G4: 0 | H4: 0 | I4: 8 | J4: 0 | K4: BEBIDAS
A5: 7891991011723 | B5: CERVEJA BUDWEISER LATA SLEEK 473ML | C5: =XLOOKUP(A5, 'Estoque 2026-01-27.xlsx'!$C:$C, 'Estoque 2026-01-27.xlsx'!$L:$L, "") | D5: =XLOOKUP(A5, 'Estoque 2026-01-27.xlsx'!$C:$C, 'Estoque 2026-01-27.xlsx'!$M:$M, "") | E5: 26 | F5: 10 | G5: 0 | H5: 0 | I5: 6 | J5: 0 | K5: BEBIDAS
A6: 7894900031515 | B6: REFRIGERANTE FANTA LARANJA PET 2L | C6: =XLOOKUP(A6, 'Estoque 2026-01-27.xlsx'!$C:$C, 'Estoque 2026-01-27.xlsx'!$L:$L, "") | D6: =XLOOKUP(A6, 'Estoque 2026-01-27.xlsx'!$C:$C, 'Estoque 2026-01-27.xlsx'!$M:$M, "") | E6: 24 | F6: 0 | G6: 0 | H6: 0 | I6: 6 | J6: 0 | K6: BEBIDAS
A7: 7894900701517 | B7: REFRIGERANTE COCA-COLA SEM AÇUCAR PET 2L | C7: =XLOOKUP(A7, 'Estoque 2026-01-27.xlsx'!$C:$C, 'Estoque 2026-01-27.xlsx'!$L:$L, "") | D7: =XLOOKUP(A7, 'Estoque 2026-01-27.xlsx'!$C:$C, 'Estoque 2026-01-27.xlsx'!$M:$M, "") | E7: 53 | F7: 7 | G7: 8 | H7: 5 | I7: 4 | J7: 0 | K7: BEBIDAS
A8: 7891991010481 | B8: CERVEJA BUDWEISER LATA SLEEK 350ML | C8: =XLOOKUP(A8, 'Estoque 2026-01-27.xlsx'!$C:$C, 'Estoque 2026-01-27.xlsx'!$L:$L, "") | D8: =XLOOKUP(A8, 'Estoque 2026-01-27.xlsx'!$C:$C, 'Estoque 2026-01-27.xlsx'!$M:$M, "") | E8: 12 | F8: 36 | G8: 0 | H8: 0 | I8: 3 | J8: 0 | K8: BEBIDAS
A9: 7894900051513 | B9: REFRIGERANTE FANTA UVA PET 2L | C9: =XLOOKUP(A9, 'Estoque 2026-01-27.xlsx'!$C:$C, 'Estoque 2026-01-27.xlsx'!$L:$L, "") | D9: =XLOOKUP(A9, 'Estoque 2026-01-27.xlsx'!$C:$C, 'Estoque 2026-01-27.xlsx'!$M:$M, "") | E9: 11 | F9: 0 | G9: 0 | H9: 0 | I9: 3 | J9: 0 | K9: BEBIDAS
A10: 7891149011001 | B10: CERVEJA CHOPP BRAHMA LATA 473ML | C10: =XLOOKUP(A10, 'Estoque 2026-01-27.xlsx'!$C:$C, 'Estoque 2026-01-27.xlsx'!$L:$L, "") | D10: =XLOOKUP(A10, 'Estoque 2026-01-27.xlsx'!$C:$C, 'Estoque 2026-01-27.xlsx'!$M:$M, "") | E10: 12 | F10: 0 | G10: 0 | H10: 0 | I10: 3 | J10: 0 | K10: BEBIDAS
A11: 7622210571601 | B11: REFRESCO EM PO TANG LARANJA 18G | C11: =XLOOKUP(A11, 'Estoque 2026-01-27.xlsx'!$C:$C, 'Estoque 2026-01-27.xlsx'!$L:$L, "") | D11: =XLOOKUP(A11, 'Estoque 2026-01-27.xlsx'!$C:$C, 'Estoque 2026-01-27.xlsx'!$M:$M, "") | E11: 11 | F11: 5 | G11: 0 | H11: 0 | I11: 3 | J11: 0 | K11: BEBIDAS
A12: 7622210571786 | B12: REFRESCO EM PO TANG UVA 18G | C12: =XLOOKUP(A12, 'Estoque 2026-01-27.xlsx'!$C:$C, 'Estoque 2026-01-27.xlsx'!$L:$L, "") | D12: =XLOOKUP(A12, 'Estoque 2026-01-27.xlsx'!$C:$C, 'Estoque 2026-01-27.xlsx'!$M:$M, "") | E12: 11 | F12: 9 | G12: 0 | H12: 0 | I12: 3 | J12: 0 | K12: BEBIDAS
A13: 7892840812423 | B13: REFRIGERANTE H2OH! LIMAO COM GAS PET 500ML | C13: =XLOOKUP(A13, 'Estoque 2026-01-27.xlsx'!$C:$C, 'Estoque 2026-01-27.xlsx'!$L:$L, "") | D13: =XLOOKUP(A13, 'Estoque 2026-01-27.xlsx'!$C:$C, 'Estoque 2026-01-27.xlsx'!$M:$M, "") | E13: 12 | F13: 0 | G13: 0 | H13: 0 | I13: 3 | J13: 0 | K13: BEBIDAS
... A20: 7892840813505 | B20: REFRIGERANTE PEPSI ZERO LATA 350ML | C20: =XLOOKUP(A20, 'Estoque 2026-01-27.xlsx'!$C:$C, 'Estoque 2026-01-27.xlsx'!$L:$L, "") | D20: =XLOOKUP(A20, 'Estoque 2026-01-27.xlsx'!$C:$C, 'Estoque 2026-01-27.xlsx'!$M:$M, "") | E20: 4 | F20: 7 | G20: 0 | H20: 0 | I20: 1 | J20: 0 | K20: BEBIDAS

Sheet BISCOITOS
A1: Código | B1: Descrição | C1: CUSTO | D1: CUSTO_MEDIO | E1: Saídas | F1: Qtd. PDV | G1: Estoque | H1: Estoque(dias) | I1: Sugestão(Un.) | J1: Qtd. mínima(Un.) | K1: CATEGORIA
A2: 7892840823153 | B2: BISCOITO FOFURA CHURRASCO 35G | C2: =XLOOKUP(A2, 'Estoque 2026-01-27.xlsx'!$C:$C, 'Estoque 2026-01-27.xlsx'!$L:$L, "") | D2: =XLOOKUP(A2, 'Estoque 2026-01-27.xlsx'!$C:$C, 'Estoque 2026-01-27.xlsx'!$M:$M, "") | E2: 29 | F2: 2 | G2: 0 | H2: 0 | I2: 7 | J2: 0 | K2: BISCOITOS
A3: 7622210592781 | B3: BISCOITO TRAKINAS MORANGO 126G | C3: =XLOOKUP(A3, 'Estoque 2026-01-27.xlsx'!$C:$C, 'Estoque 2026-01-27.xlsx'!$L:$L, "") | D3: =XLOOKUP(A3, 'Estoque 2026-01-27.xlsx'!$C:$C, 'Estoque 2026-01-27.xlsx'!$M:$M, "") | E3: 12 | F3: 0 | G3: 0 | H3: 0 | I3: 3 | J3: 0 | K3: BISCOITOS
A4: 7896024761651 | B4: BISCOITO MAIZENA PIRAQUE TRADICIONAL 175G | C4: =XLOOKUP(A4, 'Estoque 2026-01-27.xlsx'!$C:$C, 'Estoque 2026-01-27.xlsx'!$L:$L, "") | D4: =XLOOKUP(A4, 'Estoque 2026-01-27.xlsx'!$C:$C, 'Estoque 2026-01-27.xlsx'!$M:$M, "") | E4: 7 | F4: 5 | G4: 0 | H4: 0 | I4: 2 | J4: 0 | K4: BISCOITOS
A5: 7896024760401 | B5: BISCOITO RECHEADO PIRAQUE PRETTY 160G | C5: =XLOOKUP(A5, 'Estoque 2026-01-27.xlsx'!$C:$C, 'Estoque 2026-01-27.xlsx'!$L:$L, "") | D5: =XLOOKUP(A5, 'Estoque 2026-01-27.xlsx'!$C:$C, 'Estoque 2026-01-27.xlsx'!$M:$M, "") | E5: 7 | F5: 2 | G5: 0 | H5: 0 | I5: 2 | J5: 0 | K5: BISCOITOS
A6: 7892840823139 | B6: BISCOITO FOFURA CEBOLA 35G | C6: =XLOOKUP(A6, 'Estoque 2026-01-27.xlsx'!$C:$C, 'Estoque 2026-01-27.xlsx'!$L:$L, "") | D6: =XLOOKUP(A6, 'Estoque 2026-01-27.xlsx'!$C:$C, 'Estoque 2026-01-27.xlsx'!$M:$M, "") | E6: 9 | F6: 12 | G6: 0 | H6: 0 | I6: 2 | J6: 0 | K6: BISCOITOS
A7: 7896002362054 | B7: MINI BOLO ANA MARIA CHOCOLATE 42G | C7: =XLOOKUP(A7, 'Estoque 2026-01-27.xlsx'!$C:$C, 'Estoque 2026-01-27.xlsx'!$L:$L, "") | D7: =XLOOKUP(A7, 'Estoque 2026-01-27.xlsx'!$C:$C, 'Estoque 2026-01-27.xlsx'!$M:$M, "") | E7: 9 | F7: 1 | G7: 0 | H7: 0 | I7: 2 | J7: 0 | K7: BISCOITOS
A8: 7892840822866 | B8: BISCOITO SALGADO FANDANGOS QUEIJO 35G | C8: =XLOOKUP(A8, 'Estoque 2026-01-27.xlsx'!$C:$C, 'Estoque 2026-01-27.xlsx'!$L:$L, "") | D8: =XLOOKUP(A8, 'Estoque 2026-01-27.xlsx'!$C:$C, 'Estoque 2026-01-27.xlsx'!$M:$M, "") | E8: 4 | F8: 13 | G8: 0 | H8: 0 | I8: 1 | J8: 0 | K8: BISCOITOS
A9: 7892840818708 | B9: BISCOITO TODDY CHOCOLATE COOKIE 57G | C9: =XLOOKUP(A9, 'Estoque 2026-01-27.xlsx'!$C:$C, 'Estoque 2026-01-27.xlsx'!$L:$L, "") | D9: =XLOOKUP(A9, 'Estoque 2026-01-27.xlsx'!$C:$C, 'Estoque 2026-01-27.xlsx'!$M:$M, "") | E9: 3 | F9: 0 | G9: 0 | H9: 0 | I9: 1 | J9: 0 | K9: BISCOITOS
A10: 7896024760647 | B10: BISCOITO WAFER PIRAQUE CHOCOLATE 100G | C10: =XLOOKUP(A10, 'Estoque 2026-01-27.xlsx'!$C:$C, 'Estoque 2026-01-27.xlsx'!$L:$L, "") | D10: =XLOOKUP(A10, 'Estoque 2026-01-27.xlsx'!$C:$C, 'Estoque 2026-01-27.xlsx'!$M:$M, "") | E10: 3 | F10: 3 | G10: 0 | H10: 0 | I10: 1 | J10: 0 | K10: BISCOITOS
A11: 7892840822309 | B11: BISCOITO SALGADO CHEETOS MILHO ONDA 40G | C11: =XLOOKUP(A11, 'Estoque 2026-01-27.xlsx'!$C:$C, 'Estoque 2026-01-27.xlsx'!$L:$L, "") | D11: =XLOOKUP(A11, 'Estoque 2026-01-27.xlsx'!$C:$C, 'Estoque 2026-01-27.xlsx'!$M:$M, "") | E11: 6 | F11: 4 | G11: 0 | H11: 0 | I11: 1 | J11: 0 | K11: BISCOITOS
A12: 7898318333919 | B12: PIPOCAO DOCE FRANK 60G | C12: =XLOOKUP(A12, 'Estoque 2026-01-27.xlsx'!$C:$C, 'Estoque 2026-01-27.xlsx'!$L:$L, "") | D12: =XLOOKUP(A12, 'Estoque 2026-01-27.xlsx'!$C:$C, 'Estoque 2026-01-27.xlsx'!$M:$M, "") | E12: 5 | F12: 0 | G12: 0 | H12: 0 | I12: 1 | J12: 0 | K12: BISCOITOS
A13: 7892840822859 | B13: BISCOITO SALGADO FANDANGOS PRESUNTO 35G | C13: =XLOOKUP(A13, 'Estoque 2026-01-27.xlsx'!$C:$C, 'Estoque 2026-01-27.xlsx'!$L:$L, "") | D13: =XLOOKUP(A13, 'Estoque 2026-01-27.xlsx'!$C:$C, 'Estoque 2026-01-27.xlsx'!$M:$M, "") | E13: 5 | F13: 10 | G13: 0 | H13: 0 | I13: 1 | J13: 0 | K13: BISCOITOS
... A19: 7891340303233 | B19: BISCOITO WAFER ROLINHO LOOK CHOCOLATE 55G | C19: =XLOOKUP(A19, 'Estoque 2026-01-27.xlsx'!$C:$C, 'Estoque 2026-01-27.xlsx'!$L:$L, "") | D19: =XLOOKUP(A19, 'Estoque 2026-01-27.xlsx'!$C:$C, 'Estoque 2026-01-27.xlsx'!$M:$M, "") | E19: 6 | F19: 0 | G19: 0 | H19: 0 | I19: 1 | J19: 0 | K19: BISCOITOS

Sheet CHOCOLATES
A1: Código | B1: Descrição | C1: CUSTO | D1: CUSTO_MEDIO | E1: Saídas | F1: Qtd. PDV | G1: Estoque | H1: Estoque(dias) | I1: Sugestão(Un.) | J1: Qtd. mínima(Un.) | K1: CATEGORIA
A2: 7622300988517 | B2: CHOCOLATE BIS XTRA OREO 45G | C2: =XLOOKUP(A2, 'Estoque 2026-01-27.xlsx'!$C:$C, 'Estoque 2026-01-27.xlsx'!$L:$L, "") | D2: =XLOOKUP(A2, 'Estoque 2026-01-27.xlsx'!$C:$C, 'Estoque 2026-01-27.xlsx'!$M:$M, "") | E2: 30 | F2: 24 | G2: 0 | H2: 0 | I2: 7 | J2: 0 | K2: CHOCOLATES
A3: 7622300862442 | B3: CHOCOLATE BRANCO LAKA LACTA 20G | C3: =XLOOKUP(A3, 'Estoque 2026-01-27.xlsx'!$C:$C, 'Estoque 2026-01-27.xlsx'!$L:$L, "") | D3: =XLOOKUP(A3, 'Estoque 2026-01-27.xlsx'!$C:$C, 'Estoque 2026-01-27.xlsx'!$M:$M, "") | E3: 20 | F3: 0 | G3: 0 | H3: 0 | I3: 5 | J3: 0 | K3: CHOCOLATES
A4: 7622300862282 | B4: CHOCOLATE DIAMANTE NEGRO LACTA 20G | C4: =XLOOKUP(A4, 'Estoque 2026-01-27.xlsx'!$C:$C, 'Estoque 2026-01-27.xlsx'!$L:$L, "") | D4: =XLOOKUP(A4, 'Estoque 2026-01-27.xlsx'!$C:$C, 'Estoque 2026-01-27.xlsx'!$M:$M, "") | E4: 20 | F4: 0 | G4: 0 | H4: 0 | I4: 5 | J4: 0 | K4: CHOCOLATES
A5: 7622202256691 | B5: CHOCOLATE DIAMANTE NEGRO LACTA 28G | C5: =XLOOKUP(A5, 'Estoque 2026-01-27.xlsx'!$C:$C, 'Estoque 2026-01-27.xlsx'!$L:$L, "") | D5: =XLOOKUP(A5, 'Estoque 2026-01-27.xlsx'!$C:$C, 'Estoque 2026-01-27.xlsx'!$M:$M, "") | E5: 16 | F5: 20 | G5: 0 | H5: 0 | I5: 4 | J5: 0 | K5: CHOCOLATES
A6: 7891000460207 | B6: CHOCOLATE PRESTIGIO NESTLE 33G | C6: =XLOOKUP(A6, 'Estoque 2026-01-27.xlsx'!$C:$C, 'Estoque 2026-01-27.xlsx'!$L:$L, "") | D6: =XLOOKUP(A6, 'Estoque 2026-01-27.xlsx'!$C:$C, 'Estoque 2026-01-27.xlsx'!$M:$M, "") | E6: 15 | F6: 15 | G6: 0 | H6: 0 | I6: 4 | J6: 0 | K6: CHOCOLATES
A7: 78912366 | B7: CHOCOLATE BATON BRANCO 16G | C7: =XLOOKUP(A7, 'Estoque 2026-01-27.xlsx'!$C:$C, 'Estoque 2026-01-27.xlsx'!$L:$L, "") | D7: =XLOOKUP(A7, 'Estoque 2026-01-27.xlsx'!$C:$C, 'Estoque 2026-01-27.xlsx'!$M:$M, "") | E7: 13 | F7: 23 | G7: 0 | H7: 0 | I7: 3 | J7: 0 | K7: CHOCOLATES
A8: 7891000462300 | B8: CHOCOLATE CHOKITO NESTLE 32G | C8: =XLOOKUP(A8, 'Estoque 2026-01-27.xlsx'!$C:$C, 'Estoque 2026-01-27.xlsx'!$L:$L, "") | D8: =XLOOKUP(A8, 'Estoque 2026-01-27.xlsx'!$C:$C, 'Estoque 2026-01-27.xlsx'!$M:$M, "") | E8: 11 | F8: 19 | G8: 0 | H8: 0 | I8: 3 | J8: 0 | K8: CHOCOLATES
A9: 7896306625718 | B9: CHOCOLATE TRENTO CARAMELO COM AMEDOIM 25G | C9: =XLOOKUP(A9, 'Estoque 2026-01-27.xlsx'!$C:$C, 'Estoque 2026-01-27.xlsx'!$L:$L, "") | D9: =XLOOKUP(A9, 'Estoque 2026-01-27.xlsx'!$C:$C, 'Estoque 2026-01-27.xlsx'!$M:$M, "") | E9: 10 | F9: 0 | G9: 0 | H9: 0 | I9: 2 | J9: 0 | K9: CHOCOLATES
A10: 7622202256721 | B10: CHOCOLATE LAKA 28G LACTA | C10: =XLOOKUP(A10, 'Estoque 2026-01-27.xlsx'!$C:$C, 'Estoque 2026-01-27.xlsx'!$L:$L, "") | D10: =XLOOKUP(A10, 'Estoque 2026-01-27.xlsx'!$C:$C, 'Estoque 2026-01-27.xlsx'!$M:$M, "") | E10: 10 | F10: 2 | G10: 0 | H10: 0 | I10: 2 | J10: 0 | K10: CHOCOLATES
A11: 7896306625008 | B11: CHOCOLATE TRENTO IOGURTE E FRUTAS VERMELHAS 25G | C11: =XLOOKUP(A11, 'Estoque 2026-01-27.xlsx'!$C:$C, 'Estoque 2026-01-27.xlsx'!$L:$L, "") | D11: =XLOOKUP(A11, 'Estoque 2026-01-27.xlsx'!$C:$C, 'Estoque 2026-01-27.xlsx'!$M:$M, "") | E11: 7 | F11: 11 | G11: 0 | H11: 0 | I11: 2 | J11: 0 | K11: CHOCOLATES
A12: 7896306625213 | B12: WAFER TRENTO CHEESECAKE MORANGO 29G | C12: =XLOOKUP(A12, 'Estoque 2026-01-27.xlsx'!$C:$C, 'Estoque 2026-01-27.xlsx'!$L:$L, "") | D12: =XLOOKUP(A12, 'Estoque 2026-01-27.xlsx'!$C:$C, 'Estoque 2026-01-27.xlsx'!$M:$M, "") | E12: 3 | F12: 0 | G12: 0 | H12: 0 | I12: 1 | J12: 0 | K12: CHOCOLATES

Sheet CONGELADOS
A1: Código | B1: Descrição | C1: CUSTO | D1: CUSTO_MEDIO | E1: Saídas | F1: Qtd. PDV | G1: Estoque | H1: Estoque(dias) | I1: Sugestão(Un.) | J1: Qtd. mínima(Un.) | K1: CATEGORIA
A2: 7891515485528 | B2: MINI CHICKEN DE FRANGO PERDIGAO 275G | C2: =XLOOKUP(A2, 'Estoque 2026-01-27.xlsx'!$C:$C, 'Estoque 2026-01-27.xlsx'!$L:$L, "") | D2: =XLOOKUP(A2, 'Estoque 2026-01-27.xlsx'!$C:$C, 'Estoque 2026-01-27.xlsx'!$M:$M, "") | E2: 11 | F2: 7 | G2: 0 | H2: 0 | I2: 3 | J2: 0 | K2: CONGELADOS
A3: 7898945210027 | B3: BATATA FRITA QUALITY 400G | C3: =XLOOKUP(A3, 'Estoque 2026-01-27.xlsx'!$C:$C, 'Estoque 2026-01-27.xlsx'!$L:$L, "") | D3: =XLOOKUP(A3, 'Estoque 2026-01-27.xlsx'!$C:$C, 'Estoque 2026-01-27.xlsx'!$M:$M, "") | E3: 11 | F3: 7 | G3: 0 | H3: 0 | I3: 3 | J3: 0 | K3: CONGELADOS
A4: 7891515474126 | B4: STEAK DE FRANGO PERDIGAO 100G | C4: =XLOOKUP(A4, 'Estoque 2026-01-27.xlsx'!$C:$C, 'Estoque 2026-01-27.xlsx'!$L:$L, "") | D4: =XLOOKUP(A4, 'Estoque 2026-01-27.xlsx'!$C:$C, 'Estoque 2026-01-27.xlsx'!$M:$M, "") | E4: 13 | F4: 6 | G4: 0 | H4: 0 | I4: 3 | J4: 0 | K4: CONGELADOS
A5: 7894904005482 | B5: SALSICHA HOT DOG SEARA 500G | C5: =XLOOKUP(A5, 'Estoque 2026-01-27.xlsx'!$C:$C, 'Estoque 2026-01-27.xlsx'!$L:$L, "") | D5: =XLOOKUP(A5, 'Estoque 2026-01-27.xlsx'!$C:$C, 'Estoque 2026-01-27.xlsx'!$M:$M, "") | E5: 3 | F5: 0 | G5: 0 | H5: 0 | I5: 1 | J5: 0 | K5: CONGELADOS
A6: 7891515496357 | B6: LASANHA CONGELADA PERDIGAO BOLONHESA 600G | C6: =XLOOKUP(A6, 'Estoque 2026-01-27.xlsx'!$C:$C, 'Estoque 2026-01-27.xlsx'!$L:$L, "") | D6: =XLOOKUP(A6, 'Estoque 2026-01-27.xlsx'!$C:$C, 'Estoque 2026-01-27.xlsx'!$M:$M, "") | E6: 6 | F6: 0 | G6: 0 | H6: 0 | I6: 1 | J6: 0 | K6: CONGELADOS
A7: 7898921567077 | B7: BATATA FRITA CONGELADA BEM BRASIL 400G | C7: =XLOOKUP(A7, 'Estoque 2026-01-27.xlsx'!$C:$C, 'Estoque 2026-01-27.xlsx'!$L:$L, "") | D7: =XLOOKUP(A7, 'Estoque 2026-01-27.xlsx'!$C:$C, 'Estoque 2026-01-27.xlsx'!$M:$M, "") | E7: 4 | F7: 0 | G7: 0 | H7: 0 | I7: 1 | J7: 0 | K7: CONGELADOS
A8: 7893000043220 | B8: HOT POCKET SADIA CHEDDAR E BACON 145G | C8: =XLOOKUP(A8, 'Estoque 2026-01-27.xlsx'!$C:$C, 'Estoque 2026-01-27.xlsx'!$L:$L, "") | D8: =XLOOKUP(A8, 'Estoque 2026-01-27.xlsx'!$C:$C, 'Estoque 2026-01-27.xlsx'!$M:$M, "") | E8: 5 | F8: 4 | G8: 0 | H8: 0 | I8: 1 | J8: 0 | K8: CONGELADOS
A9: 7897076005434 | B9: PAO DE QUEIJO MARICOTA TRADICIONAL 1KG | C9: =XLOOKUP(A9, 'Estoque 2026-01-27.xlsx'!$C:$C, 'Estoque 2026-01-27.xlsx'!$L:$L, "") | D9: =XLOOKUP(A9, 'Estoque 2026-01-27.xlsx'!$C:$C, 'Estoque 2026-01-27.xlsx'!$M:$M, "") | E9: 3 | F9: 1 | G9: 0 | H9: 0 | I9: 1 | J9: 0 | K9: CONGELADOS
A10: 7893000394117 | B10: MARGARINA QUALY COM SAL 250G | C10: =XLOOKUP(A10, 'Estoque 2026-01-27.xlsx'!$C:$C, 'Estoque 2026-01-27.xlsx'!$L:$L, "") | D10: =XLOOKUP(A10, 'Estoque 2026-01-27.xlsx'!$C:$C, 'Estoque 2026-01-27.xlsx'!$M:$M, "") | E10: 6 | F10: 2 | G10: 0 | H10: 0 | I10: 1 | J10: 0 | K10: CONGELADOS
A11: 7891515605803 | B11: MASSA FETTUCCINE MEU MENU BOLONHESA 300G | C11: =XLOOKUP(A11, 'Estoque 2026-01-27.xlsx'!$C:$C, 'Estoque 2026-01-27.xlsx'!$L:$L, "") | D11: =XLOOKUP(A11, 'Estoque 2026-01-27.xlsx'!$C:$C, 'Estoque 2026-01-27.xlsx'!$M:$M, "") | E11: 4 | F11: 3 | G11: 0 | H11: 0 | I11: 1 | J11: 0 | K11: CONGELADOS
A12: 7893000631939 | B12: PIZZA SADIA MUCARELA 440G | C12: =XLOOKUP(A12, 'Estoque 2026-01-27.xlsx'!$C:$C, 'Estoque 2026-01-27.xlsx'!$L:$L, "") | D12: =XLOOKUP(A12, 'Estoque 2026-01-27.xlsx'!$C:$C, 'Estoque 2026-01-27.xlsx'!$M:$M, "") | E12: 5 | F12: 4 | G12: 0 | H12: 0 | I12: 1 | J12: 0 | K12: CONGELADOS
A13: 7894904678556 | B13: LASANHA REZENDE BOLONHESA 600G | C13: =XLOOKUP(A13, 'Estoque 2026-01-27.xlsx'!$C:$C, 'Estoque 2026-01-27.xlsx'!$L:$L, "") | D13: =XLOOKUP(A13, 'Estoque 2026-01-27.xlsx'!$C:$C, 'Estoque 2026-01-27.xlsx'!$M:$M, "") | E13: 5 | F13: 0 | G13: 0 | H13: 0 | I13: 1 | J13: 0 | K13: CONGELADOS
... A15: 7891515533014 | B15: PIZZA PERDIGAO CALABRESA 440G | C15: =XLOOKUP(A15, 'Estoque 2026-01-27.xlsx'!$C:$C, 'Estoque 2026-01-27.xlsx'!$L:$L, "") | D15: =XLOOKUP(A15, 'Estoque 2026-01-27.xlsx'!$C:$C, 'Estoque 2026-01-27.xlsx'!$M:$M, "") | E15: 3 | F15: 1 | G15: 0 | H15: 0 | I15: 1 | J15: 0 | K15: CONGELADOS

Sheet DOCES
A1: Código | B1: Descrição | C1: CUSTO | D1: CUSTO_MEDIO | E1: Saídas | F1: Qtd. PDV | G1: Estoque | H1: Estoque(dias) | I1: Sugestão(Un.) | J1: Qtd. mínima(Un.) | K1: CATEGORIA
A2: 7898591459474 | B2: FINI TUBES AZEDINHOS TUTTI-FRUTTI 15G | C2: =XLOOKUP(A2, 'Estoque 2026-01-27.xlsx'!$C:$C, 'Estoque 2026-01-27.xlsx'!$L:$L, "") | D2: =XLOOKUP(A2, 'Estoque 2026-01-27.xlsx'!$C:$C, 'Estoque 2026-01-27.xlsx'!$M:$M, "") | E2: 16 | F2: 0 | G2: 0 | H2: 0 | I2: 4 | J2: 0 | K2: DOCES
A3: 78938847 | B3: DROPS HALLS MORANGO 28G | C3: =XLOOKUP(A3, 'Estoque 2026-01-27.xlsx'!$C:$C, 'Estoque 2026-01-27.xlsx'!$L:$L, "") | D3: =XLOOKUP(A3, 'Estoque 2026-01-27.xlsx'!$C:$C, 'Estoque 2026-01-27.xlsx'!$M:$M, "") | E3: 12 | F3: 22 | G3: 0 | H3: 0 | I3: 3 | J3: 0 | K3: DOCES
A4: 7896336016067 | B4: PAÇOQUITA SANTA HELENA QUADRADA 20G | C4: =XLOOKUP(A4, 'Estoque 2026-01-27.xlsx'!$C:$C, 'Estoque 2026-01-27.xlsx'!$L:$L, "") | D4: =XLOOKUP(A4, 'Estoque 2026-01-27.xlsx'!$C:$C, 'Estoque 2026-01-27.xlsx'!$M:$M, "") | E4: 77 | F4: 31 | G4: 15 | H4: 6 | I4: 3 | J4: 0 | K4: DOCES
A5: 7896262301022 | B5: DROPS MASTIGAVEL FRUIT-TELLA MORANGO 640G | C5: =XLOOKUP(A5, 'Estoque 2026-01-27.xlsx'!$C:$C, 'Estoque 2026-01-27.xlsx'!$L:$L, "") | D5: =XLOOKUP(A5, 'Estoque 2026-01-27.xlsx'!$C:$C, 'Estoque 2026-01-27.xlsx'!$M:$M, "") | E5: 7 | F5: 16 | G5: 0 | H5: 0 | I5: 2 | J5: 0 | K5: DOCES
A6: 7896262304306 | B6: DROPS MENTOS STICK MINT 600G | C6: =XLOOKUP(A6, 'Estoque 2026-01-27.xlsx'!$C:$C, 'Estoque 2026-01-27.xlsx'!$L:$L, "") | D6: =XLOOKUP(A6, 'Estoque 2026-01-27.xlsx'!$C:$C, 'Estoque 2026-01-27.xlsx'!$M:$M, "") | E6: 8 | F6: 8 | G6: 0 | H6: 0 | I6: 2 | J6: 0 | K6: DOCES
A7: 7895144603063 | B7: DROPS MENTOS STICK MORANGO 600G | C7: =XLOOKUP(A7, 'Estoque 2026-01-27.xlsx'!$C:$C, 'Estoque 2026-01-27.xlsx'!$L:$L, "") | D7: =XLOOKUP(A7, 'Estoque 2026-01-27.xlsx'!$C:$C, 'Estoque 2026-01-27.xlsx'!$M:$M, "") | E7: 9 | F7: 6 | G7: 0 | H7: 0 | I7: 2 | J7: 0 | K7: DOCES
A8: 7896058500189 | B8: CONFETE DE CHOCOLATE DISQUETI 18G | C8: =XLOOKUP(A8, 'Estoque 2026-01-27.xlsx'!$C:$C, 'Estoque 2026-01-27.xlsx'!$L:$L, "") | D8: =XLOOKUP(A8, 'Estoque 2026-01-27.xlsx'!$C:$C, 'Estoque 2026-01-27.xlsx'!$M:$M, "") | E8: 7 | F8: 17 | G8: 0 | H8: 0 | I8: 2 | J8: 0 | K8: DOCES
A9: 7895800309780 | B9: CHICLETE TRIDENT MELANCIA | C9: =XLOOKUP(A9, 'Estoque 2026-01-27.xlsx'!$C:$C, 'Estoque 2026-01-27.xlsx'!$L:$L, "") | D9: =XLOOKUP(A9, 'Estoque 2026-01-27.xlsx'!$C:$C, 'Estoque 2026-01-27.xlsx'!$M:$M, "") | E9: 8 | F9: 22 | G9: 0 | H9: 0 | I9: 2 | J9: 0 | K9: DOCES
A10: 78938823 | B10: DROPS HALLS MENTOL 28G | C10: =XLOOKUP(A10, 'Estoque 2026-01-27.xlsx'!$C:$C, 'Estoque 2026-01-27.xlsx'!$L:$L, "") | D10: =XLOOKUP(A10, 'Estoque 2026-01-27.xlsx'!$C:$C, 'Estoque 2026-01-27.xlsx'!$M:$M, "") | E10: 3 | F10: 16 | G10: 0 | H10: 0 | I10: 1 | J10: 0 | K10: DOCES
A11: 78938830 | B11: DROPS HALLS MENTA 28G | C11: =XLOOKUP(A11, 'Estoque 2026-01-27.xlsx'!$C:$C, 'Estoque 2026-01-27.xlsx'!$L:$L, "") | D11: =XLOOKUP(A11, 'Estoque 2026-01-27.xlsx'!$C:$C, 'Estoque 2026-01-27.xlsx'!$M:$M, "") | E11: 4 | F11: 13 | G11: 0 | H11: 0 | I11: 1 | J11: 0 | K11: DOCES

Sheet HIGIENE PESSOAL
A1: Código | B1: Descrição | C1: CUSTO | D1: CUSTO_MEDIO | E1: Saídas | F1: Qtd. PDV | G1: Estoque | H1: Estoque(dias) | I1: Sugestão(Un.) | J1: Qtd. mínima(Un.) | K1: CATEGORIA
A2: 7896053470166 | B2: PAPEL HIGIENICO BEST LITE FOLHA DUPLA NEUTRO 4UN | C2: =XLOOKUP(A2, 'Estoque 2026-01-27.xlsx'!$C:$C, 'Estoque 2026-01-27.xlsx'!$L:$L, "") | D2: =XLOOKUP(A2, 'Estoque 2026-01-27.xlsx'!$C:$C, 'Estoque 2026-01-27.xlsx'!$M:$M, "") | E2: 4 | F2: 2 | G2: 0 | H2: 0 | I2: 1 | J2: 0 | K2: HIGIENE PESSOAL

Sheet LIMPEZA
A1: Código | B1: Descrição | C1: CUSTO | D1: CUSTO_MEDIO | E1: Saídas | F1: Qtd. PDV | G1: Estoque | H1: Estoque(dias) | I1: Sugestão(Un.) | J1: Qtd. mínima(Un.) | K1: CATEGORIA
A2: 7896021626977 | B2: DETERGENTE LIQUIDO ODD CLEAR 500ML | C2: =XLOOKUP(A2, 'Estoque 2026-01-27.xlsx'!$C:$C, 'Estoque 2026-01-27.xlsx'!$L:$L, "") | D2: =XLOOKUP(A2, 'Estoque 2026-01-27.xlsx'!$C:$C, 'Estoque 2026-01-27.xlsx'!$M:$M, "") | E2: 8 | F2: 1 | G2: 0 | H2: 0 | I2: 2 | J2: 0 | K2: LIMPEZA
A3: 7897510300125 | B3: AGUA SANITARIA BARRA 1L | C3: =XLOOKUP(A3, 'Estoque 2026-01-27.xlsx'!$C:$C, 'Estoque 2026-01-27.xlsx'!$L:$L, "") | D3: =XLOOKUP(A3, 'Estoque 2026-01-27.xlsx'!$C:$C, 'Estoque 2026-01-27.xlsx'!$M:$M, "") | E3: 7 | F3: 2 | G3: 0 | H3: 0 | I3: 2 | J3: 0 | K3: LIMPEZA
A4: 7896098909720 | B4: SABAO EM PO TIXAN YPE PRIMAV 400G | C4: =XLOOKUP(A4, 'Estoque 2026-01-27.xlsx'!$C:$C, 'Estoque 2026-01-27.xlsx'!$L:$L, "") | D4: =XLOOKUP(A4, 'Estoque 2026-01-27.xlsx'!$C:$C, 'Estoque 2026-01-27.xlsx'!$M:$M, "") | E4: 3 | F4: 1 | G4: 0 | H4: 0 | I4: 1 | J4: 0 | K4: LIMPEZA
A5: 7896021627004 | B5: DETERGENTE LIQUIDO ODD COCO 500ML | C5: =XLOOKUP(A5, 'Estoque 2026-01-27.xlsx'!$C:$C, 'Estoque 2026-01-27.xlsx'!$L:$L, "") | D5: =XLOOKUP(A5, 'Estoque 2026-01-27.xlsx'!$C:$C, 'Estoque 2026-01-27.xlsx'!$M:$M, "") | E5: 4 | F5: 2 | G5: 0 | H5: 0 | I5: 1 | J5: 0 | K5: LIMPEZA
A6: 7891035800214 | B6: LIMPADOR MULTIUSO VEJA TRADICIONAL 500ML | C6: =XLOOKUP(A6, 'Estoque 2026-01-27.xlsx'!$C:$C, 'Estoque 2026-01-27.xlsx'!$L:$L, "") | D6: =XLOOKUP(A6, 'Estoque 2026-01-27.xlsx'!$C:$C, 'Estoque 2026-01-27.xlsx'!$M:$M, "") | E6: 3 | F6: 3 | G6: 0 | H6: 0 | I6: 1 | J6: 0 | K6: LIMPEZA

Sheet MERCEARIA
A1: Código | B1: Descrição | C1: CUSTO | D1: CUSTO_MEDIO | E1: Saídas | F1: Qtd. PDV | G1: Estoque | H1: Estoque(dias) | I1: Sugestão(Un.) | J1: Qtd. mínima(Un.) | K1: CATEGORIA
A2: 7891079000229 | B2: MACARRAO INSTANTANEO NISSIN GALINHA CAIPIRA 85G | C2: =XLOOKUP(A2, 'Estoque 2026-01-27.xlsx'!$C:$C, 'Estoque 2026-01-27.xlsx'!$L:$L, "") | D2: =XLOOKUP(A2, 'Estoque 2026-01-27.xlsx'!$C:$C, 'Estoque 2026-01-27.xlsx'!$M:$M, "") | E2: 37 | F2: 10 | G2: 5 | H2: 4 | I2: 4 | J2: 0 | K2: MERCEARIA
A3: 7891095911356 | B3: MILHO PIPOCA YOKI 400G | C3: =XLOOKUP(A3, 'Estoque 2026-01-27.xlsx'!$C:$C, 'Estoque 2026-01-27.xlsx'!$L:$L, "") | D3: =XLOOKUP(A3, 'Estoque 2026-01-27.xlsx'!$C:$C, 'Estoque 2026-01-27.xlsx'!$M:$M, "") | E3: 13 | F3: 0 | G3: 0 | H3: 0 | I3: 3 | J3: 0 | K3: MERCEARIA
A4: 7896002306348 | B4: PAO DE FORMA PLUS VITA TRADICIONAL 480G | C4: =XLOOKUP(A4, 'Estoque 2026-01-27.xlsx'!$C:$C, 'Estoque 2026-01-27.xlsx'!$L:$L, "") | D4: =XLOOKUP(A4, 'Estoque 2026-01-27.xlsx'!$C:$C, 'Estoque 2026-01-27.xlsx'!$M:$M, "") | E4: 14 | F4: 2 | G4: 0 | H4: 0 | I4: 3 | J4: 0 | K4: MERCEARIA
A5: 7896292333000 | B5: MOLHO PREDILECTA TRADICIONAL SACHE 300G | C5: =XLOOKUP(A5, 'Estoque 2026-01-27.xlsx'!$C:$C, 'Estoque 2026-01-27.xlsx'!$L:$L, "") | D5: =XLOOKUP(A5, 'Estoque 2026-01-27.xlsx'!$C:$C, 'Estoque 2026-01-27.xlsx'!$M:$M, "") | E5: 9 | F5: 0 | G5: 0 | H5: 0 | I5: 2 | J5: 0 | K5: MERCEARIA
A6: 7897559900058 | B6: BATATA PALHA CRAC 60G | C6: =XLOOKUP(A6, 'Estoque 2026-01-27.xlsx'!$C:$C, 'Estoque 2026-01-27.xlsx'!$L:$L, "") | D6: =XLOOKUP(A6, 'Estoque 2026-01-27.xlsx'!$C:$C, 'Estoque 2026-01-27.xlsx'!$M:$M, "") | E6: 7 | F6: 3 | G6: 0 | H6: 0 | I6: 2 | J6: 0 | K6: MERCEARIA
A7: 7898596080000 | B7: LEITE COCO TRADICIONAL 200ML COPRA | C7: =XLOOKUP(A7, 'Estoque 2026-01-27.xlsx'!$C:$C, 'Estoque 2026-01-27.xlsx'!$L:$L, "") | D7: =XLOOKUP(A7, 'Estoque 2026-01-27.xlsx'!$C:$C, 'Estoque 2026-01-27.xlsx'!$M:$M, "") | E7: 4 | F7: 0 | G7: 0 | H7: 0 | I7: 1 | J7: 0 | K7: MERCEARIA
A8: 7896089011982 | B8: CAFE PILAO TRADICIONAL 250G | C8: =XLOOKUP(A8, 'Estoque 2026-01-27.xlsx'!$C:$C, 'Estoque 2026-01-27.xlsx'!$L:$L, "") | D8: =XLOOKUP(A8, 'Estoque 2026-01-27.xlsx'!$C:$C, 'Estoque 2026-01-27.xlsx'!$M:$M, "") | E8: 7 | F8: 4 | G8: 1 | H8: 0 | I8: 1 | J8: 0 | K8: MERCEARIA
A9: 7891000379585 | B9: ACHOCOLATADO NESCAU LATA 200G | C9: =XLOOKUP(A9, 'Estoque 2026-01-27.xlsx'!$C:$C, 'Estoque 2026-01-27.xlsx'!$L:$L, "") | D9: =XLOOKUP(A9, 'Estoque 2026-01-27.xlsx'!$C:$C, 'Estoque 2026-01-27.xlsx'!$M:$M, "") | E9: 5 | F9: 3 | G9: 0 | H9: 0 | I9: 1 | J9: 0 | K9: MERCEARIA
A10: 7891999948908 | B10: MAIONESE VIGOR SACHE 200G | C10: =XLOOKUP(A10, 'Estoque 2026-01-27.xlsx'!$C:$C, 'Estoque 2026-01-27.xlsx'!$L:$L, "") | D10: =XLOOKUP(A10, 'Estoque 2026-01-27.xlsx'!$C:$C, 'Estoque 2026-01-27.xlsx'!$M:$M, "") | E10: 5 | F10: 3 | G10: 0 | H10: 0 | I10: 1 | J10: 0 | K10: MERCEARIA
A11: 7896005286524 | B11: MACARRAO ESPAGETE SEMOLA DONA BENTA 500G | C11: =XLOOKUP(A11, 'Estoque 2026-01-27.xlsx'!$C:$C, 'Estoque 2026-01-27.xlsx'!$L:$L, "") | D11: =XLOOKUP(A11, 'Estoque 2026-01-27.xlsx'!$C:$C, 'Estoque 2026-01-27.xlsx'!$M:$M, "") | E11: 3 | F11: 1 | G11: 0 | H11: 0 | I11: 1 | J11: 0 | K11: MERCEARIA
A12: 7896292340503 | B12: MILHO PREDILECTA LATA 170G | C12: =XLOOKUP(A12, 'Estoque 2026-01-27.xlsx'!$C:$C, 'Estoque 2026-01-27.xlsx'!$L:$L, "") | D12: =XLOOKUP(A12, 'Estoque 2026-01-27.xlsx'!$C:$C, 'Estoque 2026-01-27.xlsx'!$M:$M, "") | E12: 3 | F12: 4 | G12: 0 | H12: 0 | I12: 1 | J12: 0 | K12: MERCEARIA
A13: 7891167021013 | B13: SARDINHA COM OLEO GOMES COSTA LATA 125G | C13: =XLOOKUP(A13, 'Estoque 2026-01-27.xlsx'!$C:$C, 'Estoque 2026-01-27.xlsx'!$L:$L, "") | D13: =XLOOKUP(A13, 'Estoque 2026-01-27.xlsx'!$C:$C, 'Estoque 2026-01-27.xlsx'!$M:$M, "") | E13: 5 | F13: 7 | G13: 0 | H13: 0 | I13: 1 | J13: 0 | K13: MERCEARIA
... A22: 7898917681015 | B22: XAROPE DE GUARANA GUARACAMP 1L | C22: =XLOOKUP(A22, 'Estoque 2026-01-27.xlsx'!$C:$C, 'Estoque 2026-01-27.xlsx'!$L:$L, "") | D22: =XLOOKUP(A22, 'Estoque 2026-01-27.xlsx'!$C:$C, 'Estoque 2026-01-27.xlsx'!$M:$M, "") | E22: 3 | F22: 1 | G22: 0 | H22: 0 | I22: 1 | J22: 0 | K22: MERCEARIA

Sheet OUTROS
A1: Código | B1: Descrição | C1: CUSTO | D1: CUSTO_MEDIO | E1: Saídas | F1: Qtd. PDV | G1: Estoque | H1: Estoque(dias) | I1: Sugestão(Un.) | J1: Qtd. mínima(Un.) | K1: CATEGORIA
A2: 7898964097098 | B2: ROLO ALUMINIO MELLO 30CMX4M | C2: =XLOOKUP(A2, 'Estoque 2026-01-27.xlsx'!$C:$C, 'Estoque 2026-01-27.xlsx'!$L:$L, "") | D2: =XLOOKUP(A2, 'Estoque 2026-01-27.xlsx'!$C:$C, 'Estoque 2026-01-27.xlsx'!$M:$M, "") | E2: 3 | F2: 4 | G2: 0 | H2: 0 | I2: 1 | J2: 0 | K2: OUTROS

Sheet Estoque 2026-01-27.xlsx
A1: ID Item | B1: ID produto | C1: Cód. do Produto | D1: Descrição | E1: Categoria | F1: Código de barras | G1: ID Estoque | H1: Nome Estoque | I1: Endereço do Estoque | J1: PDV Associado | K1: Último Inventário | L1: Custo da última compra | M1: Custo médio | N1: Custo total | O1: Quantidade | P1: Reservado | Q1: Mínimo crítico
A2: 342 | B2: 358 | C2: 7891991009164 | D2: CERVEJA ANTARCTICA PILSEN LATA 473ML | E2: BEBIDAS | F2: 7891991009164 | G2: 34 | H2: Estoque Central | K2: 46026.705 | L2: 3.622 | M2: 3.62 | N2: -10.86 | O2: -3 | P2: 0
A3: 2014 | B3: 727 | C3: 7622300862442 | D3: CHOCOLATE BRANCO LAKA LACTA 20G | E3: CHOCOLATES | F3: 7622300862442 | G3: 34 | H3: Estoque Central | L3: 1.9995 | M3: 2 | N3: -6 | O3: -3 | P3: 0
A4: 1641 | B4: 34 | C4: 7896024760661 | D4: BISCOITO WAFER PIRAQUE BRIGADEIRO 100G | E4: BISCOITOS | F4: 7896024760661 | G4: 34 | H4: Estoque Central | K4: 46028.748 | L4: 2.48 | M4: 2.48 | N4: -4.96 | O4: -2 | P4: 0
A5: 1917 | B5: 267 | C5: 78938823 | D5: DROPS HALLS MENTOL 28G | E5: DOCES | F5: 78938823 | G5: 34 | H5: Estoque Central | L5: 0 | M5: 0 | N5: 0 | O5: -1 | P5: 0
A6: 36 | B6: 133 | C6: 7896089012019 | D6: CAFE PILAO TRADICIONAL 500G | E6: MERCEARIA | F6: 7896089012019 | G6: 34 | H6: Estoque Central | K6: 46026.705 | L6: 29.2 | M6: 29.2 | N6: 0 | O6: 0 | P6: 0
A7: 38 | B7: 135 | C7: 7892300000698 | D7: FARINHA DE MILHO SINHA CUSCUZ 500G | E7: MERCEARIA | F7: 7892300000698 | G7: 34 | H7: Estoque Central | K7: 46026.705 | L7: 2.59 | M7: 2.59 | N7: 0 | O7: 0 | P7: 0
A8: 41 | B8: 138 | C8: 7896292300477 | D8: MOSTARDA PREDILECTA 180G | E8: MERCEARIA | F8: 7896292300477 | G8: 34 | H8: Estoque Central | K8: 46026.705 | L8: 3.39 | M8: 3.39 | N8: 0 | O8: 0 | P8: 0
A9: 43 | B9: 140 | C9: 7894000000213 | D9: CALDO KNORR GALINHA 19G | E9: MERCEARIA | F9: 7894000000213 | G9: 34 | H9: Estoque Central | K9: 46026.705 | L9: 0.87458333 | M9: 0.87 | N9: 0 | O9: 0 | P9: 0
A10: 44 | B10: 141 | C10: 7891150012370 | D10: CALDO KNORR CARNE 19G | E10: MERCEARIA | F10: 7891150012370 | G10: 34 | H10: Estoque Central | K10: 46026.705 | L10: 0.87458333 | M10: 0.87 | N10: 0 | O10: 0 | P10: 0
A11: 45 | B11: 142 | C11: 7898055421542 | D11: FARINHA AVEIA NATURALE 170G | E11: MERCEARIA | F11: 7898055421542 | G11: 34 | H11: Estoque Central | K11: 46026.705 | L11: 2.19 | M11: 2.19 | N11: 0 | O11: 0 | P11: 0
A12: 46 | B12: 143 | C12: 7898055421504 | D12: FARINHA AVEIA NATURALE FLOCOS 170G | E12: MERCEARIA | F12: 7898055421504 | G12: 34 | H12: Estoque Central | K12: 46026.705 | L12: 2.39 | M12: 2.39 | N12: 0 | O12: 0 | P12: 0
A13: 50 | B13: 147 | C13: 7896005279489 | D13: FERMENTO EM PO DONA BENTA TRADICIONAL 100G | E13: MERCEARIA | F13: 7896005279489 | G13: 34 | H13: Estoque Central | K13: 46026.705 | L13: 3.19 | M13: 3.19 | N13: 0 | O13: 0 | P13: 0
A14: 51 | B14: 148 | C14: 7896005271582 | D14: MISTURA PARA BOLO BOA SORTE BAUNILHA 400G | E14: MERCEARIA | F14: 7896005271582 | G14: 34 | H14: Estoque Central | K14: 46026.705 | L14: 4.89 | M14: 4.89 | N14: 0 | O14: 0 | P14: 0
A15: 52 | B15: 149 | C15: 7896005271599 | D15: MISTURA PARA BOLO BOA SORTE CHOCOLATE 400G | E15: MERCEARIA | F15: 7896005271599 | G15: 34 | H15: Estoque Central | K15: 46026.705 | L15: 5.49 | M15: 5.49 | N15: 0 | O15: 0 | P15: 0
A16: 53 | B16: 150 | C16: 7896005271636 | D16: MISTURA PARA BOLO BOA SORTE LARANJA 400G | E16: MERCEARIA | F16: 7896005271636 | G16: 34 | H16: Estoque Central | K16: 46026.705 | L16: 4.89 | M16: 4.89 | N16: 0 | O16: 0 | P16: 0
A17: 56 | B17: 152 | C17: 7622210592781 | D17: BISCOITO TRAKINAS MORANGO 126G | E17: BISCOITOS | F17: 7622210592781 | G17: 34 | H17: Estoque Central | K17: 46026.705 | L17: 2.35 | M17: 2.35 | N17: 0 | O17: 0 | P17: 0
... A94: 167 | B94: 325 | C94: 7894900701517 | D94: REFRIGERANTE COCA-COLA SEM AÇUCAR PET 2L | E94: BEBIDAS | F94: 7894900701517 | G94: 34 | H94: Estoque Central | K94: 46026.705 | L94: 8.49 | M94: 8.54 | N94: 68.32 | O94: 8 | P94: 0
A95: 327 | B95: 328 | C95: 7894900093056 | D95: REFRIGERANTE FANTA GUARANA PET 2L | E95: BEBIDAS | F95: 7894900093056 | G95: 1 | J95: PDV 1 - Condomínio Nova Inhaúma - Estrada Adhemar Bebiano 4906 | L95: 0 | M95: 0 | N95: 0 | O95: 0 | P95: 0 | Q95: 1
A96: 331 | B96: 341 | C96: 7892840808051 | D96: ISOTONICO GATORADE UVA PET 500ML | E96: BEBIDAS | F96: 7892840808051 | G96: 34 | H96: Estoque Central | L96: 4.4303333 | M96: 4.43 | N96: 0 | O96: 0 | P96: 0
A97: 334 | B97: 348 | C97: 9002490275013 | D97: ENERGETICO RED BULL SUMMER MARACUJA E MELAO LATA 250ML | E97: BEBIDAS | F97: 9002490275013 | G97: 34 | H97: Estoque Central | K97: 46026.705 | L97: 7.52125 | M97: 7.52 | N97: 0 | O97: 0 | P97: 0
A98: 335 | B98: 350 | C98: 7892840813444 | D98: REFRIGERANTE PEPSI ZERO PET 2L | E98: BEBIDAS | F98: 7892840813444 | G98: 34 | H98: Estoque Central | K98: 46026.705 | L98: 6.5868333 | M98: 6.59 | N98: 0 | O98: 0 | P98: 0
A99: 337 | B99: 353 | C99: 7891149010509 | D99: CERVEJA CHOPP BRAHMA LATA 350ML | E99: BEBIDAS | F99: 7891149010509 | G99: 34 | H99: Estoque Central | K99: 46026.705 | L99: 3.099 | M99: 3.1 | N99: 0 | O99: 0 | P99: 0
A100: 338 | B100: 355 | C100: 7892840808174 | D100: ISOTONICO GATORADE MORANGO E MARACUJA PET 500ML | E100: BEBIDAS | F100: 7892840808174 | G100: 34 | H100: Estoque Central | L100: 4.4303333 | M100: 4.43 | N100: 0 | O100: 0 | P100: 0
A101: 339 | B101: 356 | C101: 7891149105564 | D101: CERVEJA SKOL BEATS SENSES LATA 269ML | E101: BEBIDAS | F101: 7891149105564 | G101: 34 | H101: Estoque Central | K101: 46026.705 | L101: 5.149875 | M101: 5.15 | N101: 0 | O101: 0 | P101: 0
A102: 341 | B102: 338 | C102: 7891991000888 | D102: AGUA TONICA ANTARCTICA DIET LATA 350ML | E102: BEBIDAS | F102: 7891991000888 | G102: 34 | H102: Estoque Central | K102: 46026.705 | L102: 2.97175 | M102: 2.97 | N102: 0 | O102: 0 | P102: 0
A103: 345 | B103: 352 | C103: 7892840812423 | D103: REFRIGERANTE H2OH! LIMAO COM GAS PET 500ML | E103: BEBIDAS | F103: 7892840812423 | G103: 34 | H103: Estoque Central | L103: 3.8334167 | M103: 3.83 | N103: 0 | O103: 0 | P103: 0
A104: 350 | B104: 343 | C104: 7892840812416 | D104: REFRIGERANTE H2OH! LIMAO COM GAS PET 1,5L | E104: BEBIDAS | F104: 7892840812416 | G104: 34 | H104: Estoque Central | K104: 46026.705 | L104: 6.99 | M104: 6.99 | N104: 0 | O104: 0 | P104: 0
A105: 1529 | B105: 337 | C105: 7891340303233 | D105: BISCOITO WAFER ROLINHO LOOK CHOCOLATE 55G | E105: BISCOITOS | F105: 7891340303233 | G105: 34 | H105: Estoque Central | K105: 46028.748 | L105: 2.49 | M105: 2.49 | N105: 0 | O105: 0 | P105: 0
A106: 860 | B106: 398 | C106: 7894904575824 | D106: FETTUCINE SEARA BOLONHESA 350G | E106: CONGELADOS | F106: 7894904575824 | G106: 34 | H106: Estoque Central | K106: 46026.705 | L106: 9.69 | M106: 9.69 | N106: 0 | O106: 0 | P106: 0
A107: 862 | B107: 400 | C107: 7896085087301 | D107: MACARRAO INSTANTANEO ADRIA GALINHA 75G | E107: MERCEARIA | F107: 7896085087301 | G107: 34 | H107: Estoque Central | K107: 46026.705 | L107: 1.79 | M107: 1.79 | N107: 0 | O107: 0 | P107: 0
A108: 863 | B108: 401 | C108: 7891515605773 | D108: MASSA PENNE MEU MENU PARISIENSE 300G | E108: CONGELADOS | F108: 7891515605773 | G108: 34 | H108: Estoque Central | K108: 46026.705 | L108: 7.89 | M108: 7.89 | N108: 0 | O108: 0 | P108: 0
A109: 864 | B109: 402 | C109: 7898945210027 | D109: BATATA FRITA QUALITY 400G | E109: CONGELADOS | F109: 7898945210027 | G109: 34 | H109: Estoque Central | K109: 46026.705 | L109: 5.89 | M109: 5.89 | N109: 0 | O109: 0 | P109: 0
A110: 865 | B110: 403 | C110: 7897395020217 | D110: CERVEJA ITAIPAVA LATA 473ML | E110: BEBIDAS | F110: 7897395020217 | G110: 34 | H110: Estoque Central | K110: 46026.705 | L110: 3.95 | M110: 3.95 | N110: 0 | O110: 0 | P110: 0
A111: 859 | B111: 397 | C111: 7894904255818 | D111: PIZZA REZENDE CALABRESA 400G | E111: CONGELADOS | F111: 7894904255818 | G111: 34 | H111: Estoque Central | K111: 46026.705 | L111: 12.99 | M111: 12.99 | N111: 38.97 | O111: 3 | P111: 0
A112: 925 | B112: 430 | C112: 7896085087295 | D112: MACARRAO INSTANTANEO ADRIA GALINHA CAIPIRA 75G | E112: MERCEARIA | F112: 7896085087295 | G112: 1 | I112: 17 | J112: PDV 1 - Condomínio Nova Inhaúma - Estrada Adhemar Bebiano 4906 | L112: 0 | M112: 0 | N112: 0 | O112: 0 | P112: 0 | Q112: 0
A113: 1511 | B113: 496 | C113: 7894900531015 | D113: AGUA MINERAL CRYSTAL COM GAS PET 1,5L | E113: BEBIDAS | F113: 7894900531015 | G113: 34 | H113: Estoque Central | K113: 46026.705 | L113: 3.19 | M113: 3.19 | N113: 3.19 | O113: 1 | P113: 0
A114: 1502 | B114: 503 | C114: 7891095100934 | D114: PIPOCA YOKI MANTEIGA 100G | E114: MERCEARIA | F114: 7891095100934 | G114: 34 | H114: Estoque Central | K114: 46026.705 | L114: 4.49 | M114: 4.49 | N114: 0 | O114: 0 | P114: 0
A115: 1508 | B115: 506 | C115: 7892840818708 | D115: BISCOITO TODDY CHOCOLATE COOKIE 57G | E115: BISCOITOS | F115: 7892840818708 | G115: 34 | H115: Estoque Central | K115: 46026.705 | L115: 2.39 | M115: 2.39 | N115: 0 | O115: 0 | P115: 0
A116: 1507 | B116: 505 | C116: 7622210933454 | D116: BISCOITO MINI OREO 35G | E116: BISCOITOS | F116: 7622210933454 | G116: 34 | H116: Estoque Central | K116: 46026.705 | L116: 2.99 | M116: 2.99 | N116: 0 | O116: 0 | P116: 0
...
